<?xml version="1.0"?>
<robot name="m4k">
    <link name="base_link">
        <visual>
            <geometry>
                <box size="0.5 0.5 0.5"/>
            </geometry>
        </visual>
    </link>
    
    <link name="front_caster">
        <visual>
            <geometry>
             <cylinder length="0.05" radius="0.1" />
            </geometry>
            <material name="silver"/>
        </visual>
    </link>
    <joint name="front_caster_joint" type="continuous">
        <axis xyz="0 0 1"/>
        <parent link="base_link"/>
        <child link="front_caster"/>
        <origin rpy="0 0 0" xyz="0.25 0 -0.225"/>
    </joint>

    <link name="front_wheel">
        <visual>
            <geometry>
                <cylinder length="0.05" radius="0.075"/>
            </geometry>
            <material name="black"/>
        </visual>
    </link>
    <joint name="front_wheel_joint" type="continuous">
        <axis xyz="0 0 1"/>
        <parent link="front_caster"/>
        <child link="front_wheel"/>
        <origin rpy="-1.5708 0 0" xyz="0.05 0 -0.1"/>
    </joint>

    <link name="rear_caster">
        <visual>
            <geometry>
             <cylinder length="0.05" radius="0.1" />
            </geometry>
            <material name="silver"/>
        </visual>
    </link>
    <joint name="rear_caster_joint" type="continuous">
        <axis xyz="0 0 1"/>
        <parent link="base_link"/>
        <child link="rear_caster"/>
        <origin rpy="0 0 0" xyz="-0.25 0 -0.225"/>
    </joint>

    <link name="rear_wheel">
        <visual>
            <geometry>
                <cylinder length="0.05" radius="0.075"/>
            </geometry>
            <material name="black"/>
        </visual>
    </link>
    <joint name="rear_wheel_joint" type="continuous">
        <axis xyz="0 0 1"/>
        <parent link="rear_caster"/>
        <child link="rear_wheel"/>
        <origin rpy="-1.5708 0 0" xyz="-0.05 0 -0.1"/>
    </joint>


    <link name="right_wheel">
        <visual>
            <geometry>
             <cylinder length="0.05" radius="0.25"/>
            </geometry>
            <material name="black">
            <color rgba="0 0 0 1"/>
            </material>
        </visual>
    </link>
    <joint name="right_wheel_joint" type="continuous">
        <axis xyz="0 0 1"/>
        <parent link="base_link"/>
        <child link="right_wheel"/>
        <origin rpy="-1.5708 0 0" xyz="0 -0.275 -0.15"/>
    </joint>
    <link name="left_wheel">
        <visual>
            <geometry>
               <cylinder length="0.05" radius="0.25"/>
            </geometry>
            <material name="black"/>
        </visual>
    </link>
    <joint name="left_wheel_joint" type="continuous">
        <axis xyz="0 0 1"/>
        <parent link="base_link"/>
        <child link="left_wheel"/>
        <origin rpy="-1.5708 0 0" xyz="0 0.275 -0.15"/>
    </joint>


    <link name="led_link">
        <visual>
            <geometry>
                <box size="0.0015 0.07112 0.00889"/>
            </geometry>
            <material name="black"/>
        </visual>
    </link>
    <joint name="led_joint" type="fixed">
        <axis xyz="0 0 0"/>
        <parent link="base_link"/>
        <child link="led_link"/>
        <origin rpy="0 0 0" xyz="0.25075 0 0"/>
    </joint>

    <link name="led_id_0">
        <visual>
            <geometry>
                <box size="0.0015 0.005 0.005"/>
            </geometry>
            <material name="white">
            <color rgba="255 255 255 1"/>
            </material>
        </visual>
    </link>
    <joint name="led_id_0_joint" type="fixed">
        <axis xyz="0 0 0"/>
        <parent link="led_link"/>
        <child link="led_id_0"/>
        <origin rpy="0 0 0" xyz="0.0015 0.0315 0"/>
    </joint>

    <link name="led_id_1">
        <visual>
            <geometry>
                <box size="0.0015 0.005 0.005"/>
            </geometry>
            <material name="white">
            <color rgba="255 255 255 1"/>
            </material>
        </visual>
    </link>
    <joint name="led_id_1_joint" type="fixed">
        <axis xyz="0 0 0"/>
        <parent link="led_link"/>
        <child link="led_id_1"/>
        <origin rpy="0 0 0" xyz="0.0015 0.0225 0"/>
    </joint>

    <link name="led_id_2">
        <visual>
            <geometry>
                <box size="0.0015 0.005 0.005"/>
            </geometry>
            <material name="white">
            <color rgba="255 255 255 1"/>
            </material>
        </visual>
    </link>
    <joint name="led_id_2_joint" type="fixed">
        <axis xyz="0 0 0"/>
        <parent link="led_link"/>
        <child link="led_id_2"/>
        <origin rpy="0 0 0" xyz="0.0015 0.0135 0"/>
    </joint>

    <link name="led_id_3">
        <visual>
            <geometry>
                <box size="0.0015 0.005 0.005"/>
            </geometry>
            <material name="white">
            <color rgba="255 255 255 1"/>
            </material>
        </visual>
    </link>
    <joint name="led_id_3_joint" type="fixed">
        <axis xyz="0 0 0"/>
        <parent link="led_link"/>
        <child link="led_id_3"/>
        <origin rpy="0 0 0" xyz="0.0015 0.0045 0"/>
    </joint>

    <link name="led_id_4">
        <visual>
            <geometry>
                <box size="0.0015 0.005 0.005"/>
            </geometry>
            <material name="white">
            <color rgba="255 255 255 1"/>
            </material>
        </visual>
    </link>
    <joint name="led_id_4_joint" type="fixed">
        <axis xyz="0 0 0"/>
        <parent link="led_link"/>
        <child link="led_id_4"/>
        <origin rpy="0 0 0" xyz="0.0015 -0.0045 0"/>
    </joint>


    <link name="led_id_5">
        <visual>
            <geometry>
                <box size="0.0015 0.005 0.005"/>
            </geometry>
            <material name="white">
            <color rgba="255 255 255 1"/>
            </material>
        </visual>
    </link>
    <joint name="led_id_5_joint" type="fixed">
        <axis xyz="0 0 0"/>
        <parent link="led_link"/>
        <child link="led_id_5"/>
        <origin rpy="0 0 0" xyz="0.0015 -0.0135 0"/>
    </joint>


    <link name="led_id_6">
        <visual>
            <geometry>
                <box size="0.0015 0.005 0.005"/>
            </geometry>
            <material name="white">
            <color rgba="255 255 255 1"/>
            </material>
        </visual>
    </link>
    <joint name="led_id_6_joint" type="fixed">
        <axis xyz="0 0 0"/>
        <parent link="led_link"/>
        <child link="led_id_6"/>
        <origin rpy="0 0 0" xyz="0.0015 -0.0225 0"/>
    </joint>

    <link name="led_id_7">
        <visual>
            <geometry>
                <box size="0.0015 0.005 0.005"/>
            </geometry>
            <material name="white">
            <color rgba="255 255 255 1"/>
            </material>
        </visual>
    </link>
    <joint name="led_id_7_joint" type="fixed">
        <axis xyz="0 0 0"/>
        <parent link="led_link"/>
        <child link="led_id_7"/>
        <origin rpy="0 0 0" xyz="0.0015 -0.0315 0"/>
    </joint>
    <link name="ultrasonic">
        <visual>
            <geometry>
              <box size="0.02 0.04 0.02"/>
            </geometry>
            <material name="green">
                <color rgba="0 1 0 1"/>
            </material>
        </visual>
    </link>
    <joint name="sonar_joint" type="fixed">
        <parent link="base_link"/>
        <child link="ultrasonic"/>
        <origin xyz="0.26 0 0.1"/>
    </joint>
    <link name="laser">
        <visual>
            <geometry>
              <cylinder length="0.08" radius="0.035"/>
            </geometry>
            <material name="black"/>
        </visual>
    </link>
    <joint name="hokuyo_joint" type="fixed">
        <axis xyz="0 0 0" />
        <origin xyz="0 0 0.29" rpy="0 0 0"/>
        <parent link="base_link"/>
        <child link="laser"/>
    </joint>
</robot>