<?xml version="1.0"?>
<robot name="m4k">
    <link name="base_link">
        <visual>
            <geometry>
                <box size="0.5 0.5 0.5"/>
            </geometry>
        </visual>
    </link>

    <link name="front_caster">
        <visual>
            <geometry>
             <cylinder length="0.05" radius="0.1" />
            </geometry>
            <material name="silver"/>
        </visual>
    </link>
    <joint name="front_caster_joint" type="continuous">
        <axis xyz="0 0 1"/>
        <parent link="base_link"/>
        <child link="front_caster"/>
        <origin rpy="0 0 0" xyz="0.25 0 -0.225"/>
    </joint>

    <link name="front_wheel">
        <visual>
            <geometry>
                <cylinder length="0.05" radius="0.075"/>
            </geometry>
            <material name="black"/>
        </visual>
    </link>
    <joint name="front_wheel_joint" type="continuous">
        <axis xyz="0 0 1"/>
        <parent link="front_caster"/>
        <child link="front_wheel"/>
        <origin rpy="-1.5708 0 0" xyz="0.05 0 -0.1"/>
    </joint>

    <link name="rear_caster">
        <visual>
            <geometry>
             <cylinder length="0.05" radius="0.1" />
            </geometry>
            <material name="silver"/>
        </visual>
    </link>
    <joint name="rear_caster_joint" type="continuous">
        <axis xyz="0 0 1"/>
        <parent link="base_link"/>
        <child link="rear_caster"/>
        <origin rpy="0 0 0" xyz="-0.25 0 -0.225"/>
    </joint>

    <link name="rear_wheel">
        <visual>
            <geometry>
                <cylinder length="0.05" radius="0.075"/>
            </geometry>
            <material name="black"/>
        </visual>
    </link>
    <joint name="rear_wheel_joint" type="continuous">
        <axis xyz="0 0 1"/>
        <parent link="rear_caster"/>
        <child link="rear_wheel"/>
        <origin rpy="-1.5708 0 0" xyz="-0.05 0 -0.1"/>
    </joint>


    <link name="right_wheel">
        <visual>
            <geometry>
             <cylinder length="0.05" radius="0.25"/>
            </geometry>
            <material name="black">
            <color rgba="0 0 0 1"/>
            </material>
        </visual>
    </link>
    <joint name="right_wheel_joint" type="continuous">
        <axis xyz="0 0 1"/>
        <parent link="base_link"/>
        <child link="right_wheel"/>
        <origin rpy="-1.5708 0 0" xyz="0 -0.275 -0.15"/>
    </joint>
    <link name="left_wheel">
        <visual>
            <geometry>
               <cylinder length="0.05" radius="0.25"/>
            </geometry>
            <material name="black"/>
        </visual>
    </link>
    <joint name="left_wheel_joint" type="continuous">
        <axis xyz="0 0 1"/>
        <parent link="base_link"/>
        <child link="left_wheel"/>
        <origin rpy="-1.5708 0 0" xyz="0 0.275 -0.15"/>
    </joint>
</robot>